<mujoco model="husky">

  <!-- Mesh -->
  <compiler angle="radian" meshdir="./mesh/" autolimits="true" />

  <!-- Option -->
  <option timestep="0.002" iterations="100" solver="Newton" gravity="0 0 -9.81" integrator="RK4"></option>

  <!-- Default -->
  <default>
    <joint limited="false" armature="0.01" /> <!-- rolling joint -->
    <equality solref="0.0002 1" solimp="0.99 0.99 0.0001" />
  </default>

  <!-- Asset -->
  <asset>
    <mesh name="base_link" file="base_link.stl" />
    <mesh name="wheel" file="wheel.stl" />
    <mesh name="top_plate" file="top_plate.stl" />
    <mesh name="user_rail" file="user_rail.stl" />
    <mesh name="bumper" file="bumper.stl" />
  </asset>

  <!-- Body starts here -->
  <worldbody>

    <!-- Base -->
    <body name="base" pos="0 0 0.1" euler="0 0 0">

      <!-- Floating joint -->
      <joint type="free" name="base" />

      <!-- Visual parts -->
      <!-- If both `contype` and `conaffinity` are both 0, the corresponding `geom` is considered as
      visual geoms -->
      <geom pos="0 0 0.14493" type="mesh" contype="0" conaffinity="0" group="1" density="0"
        rgba="0.1 0.1 0.1 1" mesh="base_link" />
      <geom pos="0 0 0.14493" type="mesh" contype="0" conaffinity="0" group="1" density="0"
        rgba="0.8 0.8 0 1" mesh="top_plate" />
      <geom pos="0.272 0 0.38993" type="mesh" contype="0" conaffinity="0" group="1" density="0"
        rgba="0.3 0.3 0.3 1" mesh="user_rail" />
      <geom pos="0.48 0 0.23593" type="mesh" contype="0" conaffinity="0" group="1" density="0"
        rgba="0.3 0.3 0.3 1" mesh="bumper" />
      <geom pos="-0.48 0 0.23593" quat="1.32679e-06 0 0 1" type="mesh" contype="0" conaffinity="0"
        group="1" density="0" rgba="0.3 0.3 0.3 1" mesh="bumper" />

      <!-- Box -->
      <geom size="0.5037 0.28545 0.13375" pos="0 0 0.26991" type="box" density="100"
        rgba="0.1 0.1 0.1 0.5" />

      <!-- Left wheel -->
      <body name="front_left_wheel_link" pos="0.256 0.2854 0.17775" gravcomp="0">
        <!-- Joint -->
        <joint name="front_left_wheel" pos="0 0 0" axis="0 1 0" />
        <!-- Inertial -->
        <inertial pos="0 0 0" quat="0.5 0.5 -0.5 0.5" mass="2.637"
          diaginertia="0.04411 0.02467 0.02467" />
        <!-- Visual parts -->
        <geom type="mesh" contype="0" conaffinity="0" group="1" density="0" rgba="0.3 0.3 0.3 1"
          mesh="wheel" />
        <!-- Collision parts -->
        <geom size="0.17775 0.05715" quat="0.707107 0.707106 0 0" type="cylinder"
          rgba="0.3 0.3 0.3 0.5" />
      </body>

      <!-- Right wheel -->
      <body name="front_right_wheel_link" pos="0.256 -0.2854 0.17775" gravcomp="0">
        <!-- Joint -->
        <joint name="front_right_wheel" pos="0 0 0" axis="0 1 0" />
        <!-- Inertial -->
        <inertial pos="0 0 0" quat="0.5 0.5 -0.5 0.5" mass="2.637"
          diaginertia="0.04411 0.02467 0.02467" />
        <!-- Visual parts -->
        <geom type="mesh" contype="0" conaffinity="0" group="1" density="0" rgba="0.3 0.3 0.3 1"
          mesh="wheel" />
        <!-- Collision parts -->
        <geom size="0.17775 0.05715" quat="0.707107 0.707106 0 0" type="cylinder"
          rgba="0.3 0.3 0.3 0.5" />
      </body>

      <!-- Rear Left wheel -->
      <body name="rear_left_wheel_link" pos="-0.256 0.2854 0.17775" gravcomp="0">
        <!-- Joint -->
        <joint name="rear_left_wheel" pos="0 0 0" axis="0 1 0" />
        <!-- Inertial -->
        <inertial pos="0 0 0" quat="0.5 0.5 -0.5 0.5" mass="2.637"
          diaginertia="0.04411 0.02467 0.02467" />
        <!-- Visual parts -->
        <geom type="mesh" contype="0" conaffinity="0" group="1" density="0" rgba="0.3 0.3 0.3 1"
          mesh="wheel" />
        <!-- Collision parts -->
        <geom size="0.17775 0.05715" quat="0.707107 0.707106 0 0" type="cylinder"
          rgba="0.3 0.3 0.3 0.5" />
      </body>

      <!-- Rear Right wheel -->
      <body name="rear_right_wheel_link" pos="-0.256 -0.2854 0.17775" gravcomp="0">
        <!-- Joint -->
        <joint name="rear_right_wheel" pos="0 0 0" axis="0 1 0" />
        <!-- Inertial -->
        <inertial pos="0 0 0" quat="0.5 0.5 -0.5 0.5" mass="2.637"
          diaginertia="0.04411 0.02467 0.02467" />
        <!-- Visual parts -->
        <geom type="mesh" contype="0" conaffinity="0" group="1" density="0" rgba="0.3 0.3 0.3 1"
          mesh="wheel" />
        <!-- Collision parts -->
        <geom size="0.17775 0.05715" quat="0.707107 0.707106 0 0" type="cylinder"
          rgba="0.3 0.3 0.3 0.5" />
      </body>

    </body>

  </worldbody>

  <!-- Actuators -->
  <actuator>
    <!-- Motor
    <motor name="fl" ctrllimited="true" ctrlrange="-10.0 10.0" joint="front_left_wheel" />
    <motor name="fr" ctrllimited="true" ctrlrange="-10.0 10.0" joint="front_right_wheel" />
    <motor name="rl" ctrllimited="true" ctrlrange="-10.0 10.0" joint="rear_left_wheel" />
    <motor name="rr" ctrllimited="true" ctrlrange="-10.0 10.0" joint="rear_right_wheel" />
     -->

    <!-- Velocity -->
    <velocity name="front_left_actuator" ctrllimited="true" ctrlrange="-100.0 100.0" gear="1"
      kv="10" joint="front_left_wheel" />
    <velocity name="front_right_actuator" ctrllimited="true" ctrlrange="-100.0 100.0" gear="1"
      kv="10" joint="front_right_wheel" />
    <velocity name="rear_left_actuator" ctrllimited="true" ctrlrange="-100.0 100.0" gear="1"
      kv="10" joint="rear_left_wheel" />
    <velocity name="rear_right_actuator" ctrllimited="true" ctrlrange="-100.0 100.0" gear="1"
      kv="10" joint="rear_right_wheel" />
  </actuator>

</mujoco>