<mujoco model="go1">
  <compiler angle="radian" meshdir="assets" autolimits="true"/>

  <option cone="elliptic" impratio="100"/>

  <default>
    <default class="go1">
      <geom friction="0.6" margin="0.001" condim="1"/>
      <joint axis="0 1 0" damping="2" armature="0.01" frictionloss="0.2"/>
      <position kp="100" forcerange="-23.7 23.7"/>
      <default class="abduction">
        <joint axis="1 0 0" damping="1" range="-0.863 0.863"/>
        <position ctrlrange="-0.863 0.863"/>
      </default>
      <default class="hip">
        <joint range="-0.686 4.501"/>
        <position ctrlrange="-0.686 4.501"/>
      </default>
      <default class="knee">
        <joint range="-2.818 -0.888"/>
        <position forcerange="-35.55 35.55" ctrlrange="-2.818 -0.888"/>
      </default>
      <default class="visual">
        <geom type="mesh" contype="0" conaffinity="0" group="2" material="dark"/>
      </default>
      <default class="darker_visual">
        <geom type="mesh" contype="0" conaffinity="0" group="2" material="darker"/>
      </default>
      <default class="foot_viz">
        <geom size="0.023" pos="0 0 -0.213" type="sphere" contype="0" conaffinity="0" group="2" rgba="0.6 0.6 0.6 1"/>
      </default>
      <default class="collision">
        <geom group="3" type="capsule"/>
        <default class="hip_left1">
          <geom size="0.046 0.02" pos="0 0.045 0" quat="1 1 0 0" type="cylinder"/>
        </default>
        <default class="hip_left2">
          <geom size="0.031 0.02" pos="0 0.065 0" quat="1 1 0 0" type="cylinder"/>
        </default>
        <default class="hip_left3">
          <geom size="0.046 0.02" quat="1 1 0 0" type="cylinder"/>
        </default>
        <default class="hip_right1">
          <geom size="0.046 0.02" pos="0 -0.045 0" quat="1 1 0 0" type="cylinder"/>
        </default>
        <default class="hip_right2">
          <geom size="0.031 0.02" pos="0 -0.065 0" quat="1 1 0 0" type="cylinder"/>
        </default>
        <default class="hip_right3">
          <geom size="0.046 0.02" quat="1 1 0 0" type="cylinder"/>
        </default>
        <default class="thigh1">
          <geom size="0.015" fromto="-0.02 0 0 -0.02 0 -0.16"/>
        </default>
        <default class="thigh2">
          <geom size="0.015" fromto="0 0 0 -0.02 0 -0.1"/>
        </default>
        <default class="thigh3">
          <geom size="0.015" fromto="-0.02 0 -0.16 0 0 -0.2"/>
        </default>
        <default class="calf1">
          <geom size="0.01" fromto="0 0 0 0.02 0 -0.13"/>
        </default>
        <default class="calf2">
          <geom size="0.01" fromto="0.02 0 -0.13 0 0 -0.2"/>
        </default>
        <default class="foot">
          <geom type="sphere" size="0.023" pos="0 0 -0.213" priority="1" solimp="0.015 1 0.031" condim="6"
            friction="0.8 0.02 0.01" rgba="0 0 0 1"/>
        </default>
      </default>
    </default>
  </default>

  <asset>
    <!-- <material name="dark" rgba="0.1 0.1 0.1 1"/> -->
    <material name='white' rgba='0.5 0.5 0.5 1'/>

    <material name="dark" specular="0.5" shininess="0.5" emission="0.5" rgba="0.3 0.3 0.3 1"/>
    <material name='darker' specular="0.0" shininess="0." emission="0.2" rgba="0.2 0.2 0.2 1"/>
    <mesh class="go1" file="trunk.stl"/>
    <mesh class="go1" file="hip.stl"/>
    <mesh class="go1" file="thigh_mirror.stl"/>
    <mesh class="go1" file="calf.stl"/>
    <mesh class="go1" file="thigh.stl"/>
  </asset>

  <worldbody>
    <light name="spotlight" mode="targetbodycom" target="trunk" pos="0 -1 2"/>
    <body name="trunk" pos="0 0 0.445" childclass="go1">
      <camera name="tracking" mode="trackcom" pos="0 -1 0.8" xyaxes="1 0 0 0 1 1"/>
      <site name="head_site" pos="0.3 0 0" rgba="1 0 0 1" size="0.02" group="5"/>
      <site name="trunk_site"/>
      <inertial pos="0.0223 0.002 -0.0005" quat="-0.00342088 0.705204 0.000106698 0.708996" mass="5.204"
        diaginertia="0.0716565 0.0630105 0.0168101"/>
      <freejoint name="trunk"/>
      <geom class="darker_visual" mesh="trunk"/>
      <geom class="collision" size="0.125 0.04 0.057" type="box"/>
      <geom class="collision" quat="1 0 1 0" pos="0 -0.04 0" size="0.058 0.125" type="cylinder"/>
      <geom class="collision" quat="1 0 1 0" pos="0 +0.04 0" size="0.058 0.125" type="cylinder"/>
      <geom class="collision" pos="0.25 0 0" size="0.005 0.06 0.05" type="box"/>
      <geom class="collision" pos="0.25 0.06 -0.01" size="0.009 0.035"/>
      <geom class="collision" pos="0.25 -0.06 -0.01" size="0.009 0.035"/>
      <geom class="collision" pos="0.25 0 -0.05" size="0.01 0.06" quat="1 1 0 0"/>
      <geom class="collision" pos="0.255 0 0.0355" size="0.021 0.052" quat="1 1 0 0"/>
      <site name="imu" pos="0 0 0"/>
      <body name="FR_hip" pos="0.1881 -0.04675 0">
        <site name="FR_hip_site"/>
        <inertial pos="-0.0049166 0.00762615 -8.865e-05" quat="0.507341 0.514169 0.495027 0.482891" mass="0.68"
          diaginertia="0.000734064 0.000468438 0.000398719"/>
        <joint class="abduction" name="FR_hip_joint"/>
        <geom class="visual" mesh="hip" quat="1 0 0 0"/>
        <geom class="hip_right1"/>
        <geom class="hip_right2"/>
        <body name="FR_thigh" pos="0 -0.08 0">
          <site name="FR_thigh_site"/>
          <inertial pos="-0.00304722 0.019315 -0.0305004" quat="0.65243 -0.0272313 0.0775126 0.753383" mass="1.009"
            diaginertia="0.00478717 0.00460903 0.000709268"/>
          <joint class="hip" name="FR_thigh_joint"/>
          <geom class="visual" mesh="thigh_mirror"/>
          <geom name="FR_thigh1" class="thigh1"/>
          <geom name="FR_thigh2" class="thigh2"/>
          <geom name="FR_thigh3" class="thigh3"/>
          <body name="FR_calf" pos="0 0 -0.213">
            <site name="FR_calf_site"/>
            <inertial pos="0.00429862 0.000976676 -0.146197" quat="0.691246 0.00357467 0.00511118 0.722592"
              mass="0.195862" diaginertia="0.00149767 0.00148468 3.58427e-05"/>
            <joint class="knee" name="FR_calf_joint"/>
            <geom class="visual" mesh="calf"/>
            <geom name="FR_calf" class="calf1"/>
            <geom name="FR_foot_collision" class="calf2"/>
            <geom name="FR_foot" class="foot"/>
            <geom name="FR_vizft" class="foot_viz"/>
            <site name="FR_foot_site" pos="0 0 -0.213" type="sphere" size="0.023" group="5"/>
          </body>
        </body>
      </body>
      <body name="FL_hip" pos="0.1881 0.04675 0">
        <site name="FL_hip_site"  pos="0 0 0"/>
        <inertial pos="-0.0049166 -0.00762615 -8.865e-05" quat="0.482891 0.495027 0.514169 0.507341" mass="0.68"
          diaginertia="0.000734064 0.000468438 0.000398719"/>
        <joint class="abduction" name="FL_hip_joint"/>
        <geom class="visual" mesh="hip"/>
        <geom class="hip_left1"/>
        <geom class="hip_left2"/>
        <body name="FL_thigh" pos="0 0.08 0">
          <site name="FL_thigh_site"  pos="0 0 0"/>
          <inertial pos="-0.00304722 -0.019315 -0.0305004" quat="0.753383 0.0775126 -0.0272313 0.65243" mass="1.009"
            diaginertia="0.00478717 0.00460903 0.000709268"/>
          <joint class="hip" name="FL_thigh_joint"/>
          <geom class="visual" mesh="thigh"/>
          <geom name="FL_thigh1" class="thigh1"/>
          <geom name="FL_thigh2" class="thigh2"/>
          <geom name="FL_thigh3" class="thigh3"/>
          <body name="FL_calf" pos="0 0 -0.213">
            <site name="FL_calf_site"  pos="0 0 0"/>
            <inertial pos="0.00429862 0.000976676 -0.146197" quat="0.691246 0.00357467 0.00511118 0.722592"
              mass="0.195862" diaginertia="0.00149767 0.00148468 3.58427e-05"/>
            <joint class="knee" name="FL_calf_joint"/>
            <geom class="visual" mesh="calf"/>
            <geom name="FL_calf" class="calf1"/>
            <geom name="FL_foot_collision" class="calf2"/>
            <geom name="FL_foot" class="foot"/>
            <geom name="FL_vizft" class="foot_viz"/>
            <site name="FL_foot_site" pos="0 0 -0.213" type="sphere" size="0.023" group="5"/>
          </body>
        </body>
      </body>
      <body name="RR_hip" pos="-0.1881 -0.04675 0">
        <site name="RR_hip_site"  pos="0 0 0"/>
        <inertial pos="0.0049166 0.00762615 -8.865e-05" quat="0.495027 0.482891 0.507341 0.514169" mass="0.68"
          diaginertia="0.000734064 0.000468438 0.000398719"/>
        <joint class="abduction" name="RR_hip_joint"/>
        <geom class="visual" quat="0 0 0 -1" mesh="hip"/>
        <geom class="hip_right1"/>
        <geom class="hip_right2"/>
        <geom class="hip_right3"/>
        <body name="RR_thigh" pos="0 -0.08 0">
          <site name="RR_thigh_site"  pos="0 0 0"/>
          <inertial pos="-0.00304722 0.019315 -0.0305004" quat="0.65243 -0.0272313 0.0775126 0.753383" mass="1.009"
            diaginertia="0.00478717 0.00460903 0.000709268"/>
          <joint class="hip" name="RR_thigh_joint"/>
          <geom class="visual" mesh="thigh_mirror"/>
          <geom name="RR_thigh1" class="thigh1"/>
          <geom name="RR_thigh2" class="thigh2"/>
          <geom name="RR_thigh3" class="thigh3"/>
          <body name="RR_calf" pos="0 0 -0.213">
            <site name="RR_calf_site"  pos="0 0 0"/>
            <inertial pos="0.00429862 0.000976676 -0.146197" quat="0.691246 0.00357467 0.00511118 0.722592"
              mass="0.195862" diaginertia="0.00149767 0.00148468 3.58427e-05"/>
            <joint class="knee" name="RR_calf_joint"/>
            <geom class="visual" mesh="calf"/>
            <geom name="RR_calf" class="calf1"/>
            <geom name="RR_foot_collision" class="calf2"/>
            <geom name="RR_foot" class="foot"/>
            <geom name="RR_vizft" class="foot_viz"/>
            <site name="RR_foot_site" pos="0 0 -0.213" type="sphere" size="0.023" group="5"/>
          </body>
        </body>
      </body>
      <body name="RL_hip" pos="-0.1881 0.04675 0">
        <site name="RL_hip_site"  pos="0 0 0"/>
        <inertial pos="0.0049166 -0.00762615 -8.865e-05" quat="0.514169 0.507341 0.482891 0.495027" mass="0.68"
          diaginertia="0.000734064 0.000468438 0.000398719"/>
        <joint class="abduction" name="RL_hip_joint"/>
        <geom class="visual" quat="0 0 1 0" mesh="hip"/>
        <geom class="hip_left1"/>
        <geom class="hip_left2"/>
        <geom class="hip_left3"/>
        <body name="RL_thigh" pos="0 0.08 0">
          <site name="RL_thigh_site"  pos="0 0 0"/>
          <inertial pos="-0.00304722 -0.019315 -0.0305004" quat="0.753383 0.0775126 -0.0272313 0.65243" mass="1.009"
            diaginertia="0.00478717 0.00460903 0.000709268"/>
          <joint class="hip" name="RL_thigh_joint"/>
          <geom class="visual" mesh="thigh"/>
          <geom name="RL_thigh1"class="thigh1"/>
          <geom name="RL_thigh2"class="thigh2"/>
          <geom name="RL_thigh3"class="thigh3"/>
          <body name="RL_calf" pos="0 0 -0.213">
            <site name="RL_calf_site"  pos="0 0 0"/>
            <inertial pos="0.00429862 0.000976676 -0.146197" quat="0.691246 0.00357467 0.00511118 0.722592"
              mass="0.195862" diaginertia="0.00149767 0.00148468 3.58427e-05"/>
            <joint class="knee" name="RL_calf_joint"/>
            <geom class="visual" mesh="calf"/>
            <geom name="RL_calf" class="calf1"/>
            <geom name="RL_foot_collision" class="calf2"/>
            <geom name="RL_foot" class="foot"/>
            <geom name="RL_vizft" class="foot_viz"/>
            <site name="RL_foot_site" pos="0 0 -0.213" type="sphere" size="0.023" group="5"/>
          </body>
        </body>
      </body>
    </body>
  </worldbody>


</mujoco>
